/**:
  ros__parameters:
    robot_description: <?xml version="1.0" ?> <!-- ===================================================================================
      --> <!-- |    This document was autogenerated by xacro from /home/srl/lbr-stack/install/lbr_description/share/lbr_description/urdf/iiwa14/iiwa14.xacro
      | --> <!-- |    EDITING THIS FILE BY HAND IS NOT RECOMMENDED                                 |
      --> <!-- ===================================================================================
      --> <!-- top level --> <robot name="iiwa14"> <!-- KDL requires a link without
      inertia / Gazebo requires a connection to world link or robot will tipple https://github.com/lbr-stack/lbr_fri_ros2_stack/issues/230
      --> <link name="world"/> <!--joint between <robot_name>_world_link and robot_name_link_0-->
      <joint name="lbr_world_joint" type="fixed"> <parent link="world"/> <child link="lbr_link_0"/>
      </joint> <!-- ros_control-plugin --> <gazebo> <plugin filename="ign_ros2_control-system"
      name="ign_ros2_control::IgnitionROS2ControlPlugin"> <parameters>/home/srl/lbr-stack/install/lbr_description/share/lbr_description/ros2_control/lbr_controllers.yaml</parameters>
      <ros> <namespace>/lbr</namespace> </ros> </plugin> </gazebo> <gazebo reference="lbr_link_0">
      <mu1>0.2</mu1> <mu2>0.2</mu2> </gazebo> <gazebo reference="lbr_A1"> <implicitSpringDamper>true</implicitSpringDamper>
      <provideFeedback>true</provideFeedback> </gazebo> <gazebo reference="lbr_link_1">
      <mu1>0.2</mu1> <mu2>0.2</mu2> </gazebo> <gazebo reference="lbr_A2"> <implicitSpringDamper>true</implicitSpringDamper>
      <provideFeedback>true</provideFeedback> </gazebo> <gazebo reference="lbr_link_2">
      <mu1>0.2</mu1> <mu2>0.2</mu2> </gazebo> <gazebo reference="lbr_A3"> <implicitSpringDamper>true</implicitSpringDamper>
      <provideFeedback>true</provideFeedback> </gazebo> <gazebo reference="lbr_link_3">
      <mu1>0.2</mu1> <mu2>0.2</mu2> </gazebo> <gazebo reference="lbr_A4"> <implicitSpringDamper>true</implicitSpringDamper>
      <provideFeedback>true</provideFeedback> </gazebo> <gazebo reference="lbr_link_4">
      <mu1>0.2</mu1> <mu2>0.2</mu2> </gazebo> <gazebo reference="lbr_A5"> <implicitSpringDamper>true</implicitSpringDamper>
      <provideFeedback>true</provideFeedback> </gazebo> <gazebo reference="lbr_link_5">
      <mu1>0.2</mu1> <mu2>0.2</mu2> </gazebo> <gazebo reference="lbr_A6"> <implicitSpringDamper>true</implicitSpringDamper>
      <provideFeedback>true</provideFeedback> </gazebo> <gazebo reference="lbr_link_6">
      <mu1>0.2</mu1> <mu2>0.2</mu2> </gazebo> <gazebo reference="lbr_A7"> <implicitSpringDamper>true</implicitSpringDamper>
      <provideFeedback>true</provideFeedback> </gazebo> <gazebo reference="lbr_link_7">
      <mu1>0.2</mu1> <mu2>0.2</mu2> </gazebo> <ros2_control name="lbr_system_interface"
      type="system"> <hardware> <plugin>lbr_ros2_control::SystemInterface</plugin>
      <param name="fri_client_sdk_major_version">2</param> <param name="fri_client_sdk_minor_version">15</param>
      <param name="client_command_mode">position</param> <param name="port_id">30200</param>
      <param name="remote_host">INADDR_ANY</param> <param name="rt_prio">80</param>
      <param name="joint_position_tau">0.04</param> <param name="command_guard_variant">default</param>
      <param name="external_torque_tau">0.04</param> <param name="measured_torque_tau">0.04</param>
      <param name="open_loop">True</param> </hardware> <sensor name="auxiliary_sensor">
      <!-- see KUKA::FRI::LBRState --> <state_interface name="sample_time"/> <state_interface
      name="session_state"/> <state_interface name="connection_quality"/> <state_interface
      name="safety_state"/> <state_interface name="operation_mode"/> <state_interface
      name="drive_state"/> <state_interface name="client_command_mode"/> <state_interface
      name="overlay_type"/> <state_interface name="control_mode"/> <state_interface
      name="time_stamp_sec"/> <state_interface name="time_stamp_nano_sec"/> <state_interface
      name="tracking_performance"/> </sensor> <sensor name="estimated_ft_sensor">
      <param name="enabled">True</param> <param name="update_rate">100</param> <param
      name="rt_prio">30</param> <param name="chain_root">lbr_link_0</param> <param
      name="chain_tip">lbr_link_ee</param> <param name="damping">0.2</param> <param
      name="force_x_th">2.0</param> <param name="force_y_th">2.0</param> <param name="force_z_th">2.0</param>
      <param name="torque_x_th">0.5</param> <param name="torque_y_th">0.5</param>
      <param name="torque_z_th">0.5</param> <state_interface name="force.x"/> <state_interface
      name="force.y"/> <state_interface name="force.z"/> <state_interface name="torque.x"/>
      <state_interface name="torque.y"/> <state_interface name="torque.z"/> </sensor>
      <!-- FRI Cartesian impedance control mode --> <gpio name="wrench"> <command_interface
      name="force.x"/> <command_interface name="force.y"/> <command_interface name="force.z"/>
      <command_interface name="torque.x"/> <command_interface name="torque.y"/> <command_interface
      name="torque.z"/> </gpio> <joint name="lbr_A1"> <command_interface name="position">
      <param name="min">-2.9670597283903604</param> <param name="max">2.9670597283903604</param>
      </command_interface> <command_interface name="effort"> <param name="min">-200</param>
      <param name="max"> 200</param> </command_interface> <state_interface name="position"/>
      <state_interface name="velocity"/> <state_interface name="effort"/> <param name="min_position">-2.9670597283903604</param>
      <param name="max_position">2.9670597283903604</param> <param name="max_velocity">1.4835298641951802</param>
      <param name="max_torque">200</param> <state_interface name="commanded_torque"/>
      <state_interface name="external_torque"/> <state_interface name="ipo_joint_position"/>
      </joint> <joint name="lbr_A2"> <command_interface name="position"> <param name="min">-2.0943951023931953</param>
      <param name="max">2.0943951023931953</param> </command_interface> <command_interface
      name="effort"> <param name="min">-200</param> <param name="max"> 200</param>
      </command_interface> <state_interface name="position"/> <state_interface name="velocity"/>
      <state_interface name="effort"/> <param name="min_position">-2.0943951023931953</param>
      <param name="max_position">2.0943951023931953</param> <param name="max_velocity">1.4835298641951802</param>
      <param name="max_torque">200</param> <state_interface name="commanded_torque"/>
      <state_interface name="external_torque"/> <state_interface name="ipo_joint_position"/>
      </joint> <joint name="lbr_A3"> <command_interface name="position"> <param name="min">-2.9670597283903604</param>
      <param name="max">2.9670597283903604</param> </command_interface> <command_interface
      name="effort"> <param name="min">-200</param> <param name="max"> 200</param>
      </command_interface> <state_interface name="position"/> <state_interface name="velocity"/>
      <state_interface name="effort"/> <param name="min_position">-2.9670597283903604</param>
      <param name="max_position">2.9670597283903604</param> <param name="max_velocity">1.7453292519943295</param>
      <param name="max_torque">200</param> <state_interface name="commanded_torque"/>
      <state_interface name="external_torque"/> <state_interface name="ipo_joint_position"/>
      </joint> <joint name="lbr_A4"> <command_interface name="position"> <param name="min">-2.0943951023931953</param>
      <param name="max">2.0943951023931953</param> </command_interface> <command_interface
      name="effort"> <param name="min">-200</param> <param name="max"> 200</param>
      </command_interface> <state_interface name="position"/> <state_interface name="velocity"/>
      <state_interface name="effort"/> <param name="min_position">-2.0943951023931953</param>
      <param name="max_position">2.0943951023931953</param> <param name="max_velocity">1.3089969389957472</param>
      <param name="max_torque">200</param> <state_interface name="commanded_torque"/>
      <state_interface name="external_torque"/> <state_interface name="ipo_joint_position"/>
      </joint> <joint name="lbr_A5"> <command_interface name="position"> <param name="min">-2.9670597283903604</param>
      <param name="max">2.9670597283903604</param> </command_interface> <command_interface
      name="effort"> <param name="min">-200</param> <param name="max"> 200</param>
      </command_interface> <state_interface name="position"/> <state_interface name="velocity"/>
      <state_interface name="effort"/> <param name="min_position">-2.9670597283903604</param>
      <param name="max_position">2.9670597283903604</param> <param name="max_velocity">2.2689280275926285</param>
      <param name="max_torque">200</param> <state_interface name="commanded_torque"/>
      <state_interface name="external_torque"/> <state_interface name="ipo_joint_position"/>
      </joint> <joint name="lbr_A6"> <command_interface name="position"> <param name="min">-2.0943951023931953</param>
      <param name="max">2.0943951023931953</param> </command_interface> <command_interface
      name="effort"> <param name="min">-200</param> <param name="max"> 200</param>
      </command_interface> <state_interface name="position"/> <state_interface name="velocity"/>
      <state_interface name="effort"/> <param name="min_position">-2.0943951023931953</param>
      <param name="max_position">2.0943951023931953</param> <param name="max_velocity">2.356194490192345</param>
      <param name="max_torque">200</param> <state_interface name="commanded_torque"/>
      <state_interface name="external_torque"/> <state_interface name="ipo_joint_position"/>
      </joint> <joint name="lbr_A7"> <command_interface name="position"> <param name="min">-3.0543261909900763</param>
      <param name="max">3.0543261909900763</param> </command_interface> <command_interface
      name="effort"> <param name="min">-200</param> <param name="max"> 200</param>
      </command_interface> <state_interface name="position"/> <state_interface name="velocity"/>
      <state_interface name="effort"/> <param name="min_position">-3.0543261909900763</param>
      <param name="max_position">3.0543261909900763</param> <param name="max_velocity">2.356194490192345</param>
      <param name="max_torque">200</param> <state_interface name="commanded_torque"/>
      <state_interface name="external_torque"/> <state_interface name="ipo_joint_position"/>
      </joint> </ros2_control> <link name="lbr_link_0"> <inertial> <origin rpy="0
      0 0" xyz="-0.012822 0.0 0.071507"/> <mass value="7.050378"/> <inertia ixx="0.031226"
      ixy="0.0" ixz="0.000871" iyy="0.039697" iyz="0.0" izz="0.043102"/> </inertial>
      <visual> <origin rpy="0 0 0" xyz="0 0 0"/> <geometry> <mesh filename="package://lbr_description/meshes/iiwa14/visual/link_0.dae"/>
      </geometry> </visual> <collision> <origin rpy="0 0 0" xyz="0 0 0"/> <geometry>
      <mesh filename="package://lbr_description/meshes/iiwa14/collision/link_0.stl"/>
      </geometry> </collision> </link> <joint name="lbr_A1" type="revolute"> <origin
      rpy="0 0 0" xyz="0.0 0.0 0.1475"/> <parent link="lbr_link_0"/> <child link="lbr_link_1"/>
      <axis xyz="0.0 0.0 1.0"/> <limit effort="200" lower="-2.9670597283903604" upper="2.9670597283903604"
      velocity="1.4835298641951802"/> <dynamics damping="10.0" friction="0.1"/> </joint>
      <link name="lbr_link_1"> <inertial> <origin rpy="0 0 0" xyz="0.0 -0.033795 0.132404"/>
      <mass value="5.289529"/> <inertia ixx="0.042462" ixy="0.0" ixz="0.0" iyy="0.042838"
      iyz="0.006341" izz="0.01587"/> </inertial> <visual> <origin rpy="0 0 0" xyz="0.0
      0.0 -0.1475"/> <geometry> <mesh filename="package://lbr_description/meshes/iiwa14/visual/link_1.dae"/>
      </geometry> </visual> <collision> <origin rpy="0 0 0" xyz="0.0 0.0 -0.1475"/>
      <geometry> <mesh filename="package://lbr_description/meshes/iiwa14/collision/link_1.stl"/>
      </geometry> </collision> </link> <joint name="lbr_A2" type="revolute"> <origin
      rpy="0 0 0" xyz="0.0 -0.01 0.2125"/> <parent link="lbr_link_1"/> <child link="lbr_link_2"/>
      <axis xyz="0.0 1.0 0.0"/> <limit effort="200" lower="-2.0943951023931953" upper="2.0943951023931953"
      velocity="1.4835298641951802"/> <dynamics damping="10.0" friction="0.1"/> </joint>
      <link name="lbr_link_2"> <inertial> <origin rpy="0 0 0" xyz="0.000136 0.047548
      0.076322"/> <mass value="5.688888"/> <inertia ixx="0.055182" ixy="-3.3e-05"
      ixz="5.6e-05" iyy="0.053983" iyz="0.010034" izz="0.016523"/> </inertial> <visual>
      <origin rpy="0 0 0" xyz="0.0 0.01 -0.36"/> <geometry> <mesh filename="package://lbr_description/meshes/iiwa14/visual/link_2.dae"/>
      </geometry> </visual> <collision> <origin rpy="0 0 0" xyz="0.0 0.01 -0.36"/>
      <geometry> <mesh filename="package://lbr_description/meshes/iiwa14/collision/link_2.stl"/>
      </geometry> </collision> </link> <joint name="lbr_A3" type="revolute"> <origin
      rpy="0 0 0" xyz="0.0 0.01 0.228"/> <parent link="lbr_link_2"/> <child link="lbr_link_3"/>
      <axis xyz="0.0 0.0 1.0"/> <limit effort="200" lower="-2.9670597283903604" upper="2.9670597283903604"
      velocity="1.7453292519943295"/> <dynamics damping="10.0" friction="0.1"/> </joint>
      <link name="lbr_link_3"> <inertial> <origin rpy="0 0 0" xyz="0.0 0.034913 0.123108"/>
      <mass value="3.461245"/> <inertia ixx="0.02172" ixy="0.0" ixz="0.0" iyy="0.02073"
      iyz="-0.003845" izz="0.007701"/> </inertial> <visual> <origin rpy="0 0 0" xyz="0.0
      0.0 -0.588"/> <geometry> <mesh filename="package://lbr_description/meshes/iiwa14/visual/link_3.dae"/>
      </geometry> </visual> <collision> <origin rpy="0 0 0" xyz="0.0 0.0 -0.588"/>
      <geometry> <mesh filename="package://lbr_description/meshes/iiwa14/collision/link_3.stl"/>
      </geometry> </collision> </link> <joint name="lbr_A4" type="revolute"> <origin
      rpy="0 0 0" xyz="0.0 0.0105 0.192"/> <parent link="lbr_link_3"/> <child link="lbr_link_4"/>
      <axis xyz="0.0 -1.0 0.0"/> <limit effort="200" lower="-2.0943951023931953" upper="2.0943951023931953"
      velocity="1.3089969389957472"/> <dynamics damping="10.0" friction="0.1"/> </joint>
      <link name="lbr_link_4"> <inertial> <origin rpy="0 0 0" xyz="0.0 -0.039793 0.086944"/>
      <mass value="4.122995"/> <inertia ixx="0.03241" ixy="0.0" ixz="0.0" iyy="0.030758"
      iyz="-0.006022" izz="0.009883"/> </inertial> <visual> <origin rpy="0 0 0" xyz="0.0
      -0.0105 -0.78"/> <geometry> <mesh filename="package://lbr_description/meshes/iiwa14/visual/link_4.dae"/>
      </geometry> </visual> <collision> <origin rpy="0 0 0" xyz="0.0 -0.0105 -0.78"/>
      <geometry> <mesh filename="package://lbr_description/meshes/iiwa14/collision/link_4.stl"/>
      </geometry> </collision> </link> <joint name="lbr_A5" type="revolute"> <origin
      rpy="0 0 0" xyz="0.0 -0.0105 0.2075"/> <parent link="lbr_link_4"/> <child link="lbr_link_5"/>
      <axis xyz="0.0 0.0 1.0"/> <limit effort="200" lower="-2.9670597283903604" upper="2.9670597283903604"
      velocity="2.2689280275926285"/> <dynamics damping="10.0" friction="0.1"/> </joint>
      <link name="lbr_link_5"> <inertial> <origin rpy="0 0 0" xyz="0.0 -0.029824 0.076267"/>
      <mass value="1.563756"/> <inertia ixx="0.008677" ixy="0.0" ixz="0.0" iyy="0.007297"
      iyz="0.002869" izz="0.003935"/> </inertial> <visual> <origin rpy="0 0 0" xyz="0.0
      0.0 -0.9875"/> <geometry> <mesh filename="package://lbr_description/meshes/iiwa14/visual/link_5.dae"/>
      </geometry> </visual> <collision> <origin rpy="0 0 0" xyz="0.0 0.0 -0.9875"/>
      <geometry> <mesh filename="package://lbr_description/meshes/iiwa14/collision/link_5.stl"/>
      </geometry> </collision> </link> <joint name="lbr_A6" type="revolute"> <origin
      rpy="0 0 0" xyz="0.0 -0.0707 0.1925"/> <parent link="lbr_link_5"/> <child link="lbr_link_6"/>
      <axis xyz="0.0 1.0 0.0"/> <limit effort="200" lower="-2.0943951023931953" upper="2.0943951023931953"
      velocity="2.356194490192345"/> <dynamics damping="10.0" friction="0.1"/> </joint>
      <link name="lbr_link_6"> <inertial> <origin rpy="0 0 0" xyz="0.0 0.07102 0.00495"/>
      <mass value="2.457878"/> <inertia ixx="0.007227" ixy="0.0" ixz="0.0" iyy="0.006958"
      iyz="0.000318" izz="0.004734"/> </inertial> <visual> <origin rpy="0 0 0" xyz="0.0
      0.0707 -1.18"/> <geometry> <mesh filename="package://lbr_description/meshes/iiwa14/visual/link_6.dae"/>
      </geometry> </visual> <collision> <origin rpy="0 0 0" xyz="0.0 0.0707 -1.18"/>
      <geometry> <mesh filename="package://lbr_description/meshes/iiwa14/collision/link_6.stl"/>
      </geometry> </collision> </link> <joint name="lbr_A7" type="revolute"> <origin
      rpy="0 0 0" xyz="0.0 0.0707 0.091"/> <parent link="lbr_link_6"/> <child link="lbr_link_7"/>
      <axis xyz="0.0 0.0 1.0"/> <limit effort="200" lower="-3.0543261909900763" upper="3.0543261909900763"
      velocity="2.356194490192345"/> <dynamics damping="10.0" friction="0.1"/> </joint>
      <link name="lbr_link_7"> <inertial> <origin rpy="0 0 0" xyz="3.0000e-06 -2.0000e-06
      1.3782e-02"/> <mass value="0.265331"/> <inertia ixx="0.000175" ixy="0.0" ixz="0.0"
      iyy="0.000175" iyz="0.0" izz="0.000306"/> </inertial> <visual> <origin rpy="0
      0 0" xyz="0.0 0.0 -1.271"/> <geometry> <mesh filename="package://lbr_description/meshes/iiwa14/visual/link_7.dae"/>
      </geometry> </visual> <collision> <origin rpy="0 0 0" xyz="0.0 0.0 -1.271"/>
      <geometry> <mesh filename="package://lbr_description/meshes/iiwa14/collision/link_7.stl"/>
      </geometry> </collision> </link> <joint name="lbr_joint_ee" type="fixed"> <parent
      link="lbr_link_7"/> <child link="lbr_link_ee"/> <origin rpy="0 0 0" xyz="0 0
      0.035"/> </joint> <link name="lbr_link_ee"> </link> </robot>
